Not Found: /
[33mHTTP GET / 404 [0.01, 127.0.0.1:49000][0m
Internal Server Error: /chat/default/
Traceback (most recent call last):
  File "/home/user-deb/Documents/Projects/django-chat-app/djangovenv/lib/python3.11/site-packages/django/db/models/query.py", line 916, in get_or_create
    return self.get(**kwargs), False
           ^^^^^^^^^^^^^^^^^^
  File "/home/user-deb/Documents/Projects/django-chat-app/djangovenv/lib/python3.11/site-packages/django/db/models/query.py", line 637, in get
    raise self.model.DoesNotExist(
chat.models.Chat.DoesNotExist: Chat matching query does not exist.

During handling of the above exception, another exception occurred:

Traceback (most recent call last):
  File "/home/user-deb/Documents/Projects/django-chat-app/djangovenv/lib/python3.11/site-packages/django/db/backends/utils.py", line 89, in _execute
    return self.cursor.execute(sql, params)
           ^^^^^^^^^^^^^^^^^^^^^^^^^^^^^^^^
  File "/home/user-deb/Documents/Projects/django-chat-app/djangovenv/lib/python3.11/site-packages/django/db/backends/sqlite3/base.py", line 328, in execute
    return super().execute(query, params)
           ^^^^^^^^^^^^^^^^^^^^^^^^^^^^^^
sqlite3.IntegrityError: NOT NULL constraint failed: chat.id

The above exception was the direct cause of the following exception:

Traceback (most recent call last):
  File "/home/user-deb/Documents/Projects/django-chat-app/djangovenv/lib/python3.11/site-packages/asgiref/sync.py", line 534, in thread_handler
    raise exc_info[1]
  File "/home/user-deb/Documents/Projects/django-chat-app/djangovenv/lib/python3.11/site-packages/django/core/handlers/exception.py", line 42, in inner
    response = await get_response(request)
               ^^^^^^^^^^^^^^^^^^^^^^^^^^^
  File "/home/user-deb/Documents/Projects/django-chat-app/djangovenv/lib/python3.11/site-packages/asgiref/sync.py", line 534, in thread_handler
    raise exc_info[1]
  File "/home/user-deb/Documents/Projects/django-chat-app/djangovenv/lib/python3.11/site-packages/django/core/handlers/base.py", line 253, in _get_response_async
    response = await wrapped_callback(
               ^^^^^^^^^^^^^^^^^^^^^^^
  File "/home/user-deb/Documents/Projects/django-chat-app/djangovenv/lib/python3.11/site-packages/asgiref/sync.py", line 479, in __call__
    ret: _R = await loop.run_in_executor(
              ^^^^^^^^^^^^^^^^^^^^^^^^^^^
  File "/usr/lib/python3.11/concurrent/futures/thread.py", line 58, in run
    result = self.fn(*self.args, **self.kwargs)
             ^^^^^^^^^^^^^^^^^^^^^^^^^^^^^^^^^^
  File "/home/user-deb/Documents/Projects/django-chat-app/djangovenv/lib/python3.11/site-packages/asgiref/sync.py", line 538, in thread_handler
    return func(*args, **kwargs)
           ^^^^^^^^^^^^^^^^^^^^^
  File "/home/user-deb/Documents/Projects/django-chat-app/chat/views.py", line 8, in chat_view
    chat, created = Chat.objects.get_or_create(name=chat_name)
                    ^^^^^^^^^^^^^^^^^^^^^^^^^^^^^^^^^^^^^^^^^^
  File "/home/user-deb/Documents/Projects/django-chat-app/djangovenv/lib/python3.11/site-packages/django/db/models/manager.py", line 87, in manager_method
    return getattr(self.get_queryset(), name)(*args, **kwargs)
           ^^^^^^^^^^^^^^^^^^^^^^^^^^^^^^^^^^^^^^^^^^^^^^^^^^^
  File "/home/user-deb/Documents/Projects/django-chat-app/djangovenv/lib/python3.11/site-packages/django/db/models/query.py", line 923, in get_or_create
    return self.create(**params), True
           ^^^^^^^^^^^^^^^^^^^^^
  File "/home/user-deb/Documents/Projects/django-chat-app/djangovenv/lib/python3.11/site-packages/django/db/models/query.py", line 658, in create
    obj.save(force_insert=True, using=self.db)
  File "/home/user-deb/Documents/Projects/django-chat-app/chat/models.py", line 62, in save
    super().save(*args, **kwargs)
  File "/home/user-deb/Documents/Projects/django-chat-app/djangovenv/lib/python3.11/site-packages/django/db/models/base.py", line 814, in save
    self.save_base(
  File "/home/user-deb/Documents/Projects/django-chat-app/djangovenv/lib/python3.11/site-packages/django/db/models/base.py", line 877, in save_base
    updated = self._save_table(
              ^^^^^^^^^^^^^^^^^
  File "/home/user-deb/Documents/Projects/django-chat-app/djangovenv/lib/python3.11/site-packages/django/db/models/base.py", line 1020, in _save_table
    results = self._do_insert(
              ^^^^^^^^^^^^^^^^
  File "/home/user-deb/Documents/Projects/django-chat-app/djangovenv/lib/python3.11/site-packages/django/db/models/base.py", line 1061, in _do_insert
    return manager._insert(
           ^^^^^^^^^^^^^^^^
  File "/home/user-deb/Documents/Projects/django-chat-app/djangovenv/lib/python3.11/site-packages/django/db/models/manager.py", line 87, in manager_method
    return getattr(self.get_queryset(), name)(*args, **kwargs)
           ^^^^^^^^^^^^^^^^^^^^^^^^^^^^^^^^^^^^^^^^^^^^^^^^^^^
  File "/home/user-deb/Documents/Projects/django-chat-app/djangovenv/lib/python3.11/site-packages/django/db/models/query.py", line 1805, in _insert
    return query.get_compiler(using=using).execute_sql(returning_fields)
           ^^^^^^^^^^^^^^^^^^^^^^^^^^^^^^^^^^^^^^^^^^^^^^^^^^^^^^^^^^^^^
  File "/home/user-deb/Documents/Projects/django-chat-app/djangovenv/lib/python3.11/site-packages/django/db/models/sql/compiler.py", line 1822, in execute_sql
    cursor.execute(sql, params)
  File "/home/user-deb/Documents/Projects/django-chat-app/djangovenv/lib/python3.11/site-packages/django/db/backends/utils.py", line 102, in execute
    return super().execute(sql, params)
           ^^^^^^^^^^^^^^^^^^^^^^^^^^^^
  File "/home/user-deb/Documents/Projects/django-chat-app/djangovenv/lib/python3.11/site-packages/django/db/backends/utils.py", line 67, in execute
    return self._execute_with_wrappers(
           ^^^^^^^^^^^^^^^^^^^^^^^^^^^^
  File "/home/user-deb/Documents/Projects/django-chat-app/djangovenv/lib/python3.11/site-packages/django/db/backends/utils.py", line 80, in _execute_with_wrappers
    return executor(sql, params, many, context)
           ^^^^^^^^^^^^^^^^^^^^^^^^^^^^^^^^^^^^
  File "/home/user-deb/Documents/Projects/django-chat-app/djangovenv/lib/python3.11/site-packages/django/db/backends/utils.py", line 84, in _execute
    with self.db.wrap_database_errors:
  File "/home/user-deb/Documents/Projects/django-chat-app/djangovenv/lib/python3.11/site-packages/django/db/utils.py", line 91, in __exit__
    raise dj_exc_value.with_traceback(traceback) from exc_value
  File "/home/user-deb/Documents/Projects/django-chat-app/djangovenv/lib/python3.11/site-packages/django/db/backends/utils.py", line 89, in _execute
    return self.cursor.execute(sql, params)
           ^^^^^^^^^^^^^^^^^^^^^^^^^^^^^^^^
  File "/home/user-deb/Documents/Projects/django-chat-app/djangovenv/lib/python3.11/site-packages/django/db/backends/sqlite3/base.py", line 328, in execute
    return super().execute(query, params)
           ^^^^^^^^^^^^^^^^^^^^^^^^^^^^^^
django.db.utils.IntegrityError: NOT NULL constraint failed: chat.id
[35;1mHTTP GET /chat/default/ 500 [0.03, 127.0.0.1:49000][0m
Internal Server Error: /chat/testing/
Traceback (most recent call last):
  File "/home/user-deb/Documents/Projects/django-chat-app/djangovenv/lib/python3.11/site-packages/django/db/models/query.py", line 916, in get_or_create
    return self.get(**kwargs), False
           ^^^^^^^^^^^^^^^^^^
  File "/home/user-deb/Documents/Projects/django-chat-app/djangovenv/lib/python3.11/site-packages/django/db/models/query.py", line 637, in get
    raise self.model.DoesNotExist(
chat.models.Chat.DoesNotExist: Chat matching query does not exist.

During handling of the above exception, another exception occurred:

Traceback (most recent call last):
  File "/home/user-deb/Documents/Projects/django-chat-app/djangovenv/lib/python3.11/site-packages/django/db/backends/utils.py", line 89, in _execute
    return self.cursor.execute(sql, params)
           ^^^^^^^^^^^^^^^^^^^^^^^^^^^^^^^^
  File "/home/user-deb/Documents/Projects/django-chat-app/djangovenv/lib/python3.11/site-packages/django/db/backends/sqlite3/base.py", line 328, in execute
    return super().execute(query, params)
           ^^^^^^^^^^^^^^^^^^^^^^^^^^^^^^
sqlite3.IntegrityError: NOT NULL constraint failed: chat.id

The above exception was the direct cause of the following exception:

Traceback (most recent call last):
  File "/home/user-deb/Documents/Projects/django-chat-app/djangovenv/lib/python3.11/site-packages/asgiref/sync.py", line 534, in thread_handler
    raise exc_info[1]
  File "/home/user-deb/Documents/Projects/django-chat-app/djangovenv/lib/python3.11/site-packages/django/core/handlers/exception.py", line 42, in inner
    response = await get_response(request)
               ^^^^^^^^^^^^^^^^^^^^^^^^^^^
  File "/home/user-deb/Documents/Projects/django-chat-app/djangovenv/lib/python3.11/site-packages/asgiref/sync.py", line 534, in thread_handler
    raise exc_info[1]
  File "/home/user-deb/Documents/Projects/django-chat-app/djangovenv/lib/python3.11/site-packages/django/core/handlers/base.py", line 253, in _get_response_async
    response = await wrapped_callback(
               ^^^^^^^^^^^^^^^^^^^^^^^
  File "/home/user-deb/Documents/Projects/django-chat-app/djangovenv/lib/python3.11/site-packages/asgiref/sync.py", line 479, in __call__
    ret: _R = await loop.run_in_executor(
              ^^^^^^^^^^^^^^^^^^^^^^^^^^^
  File "/usr/lib/python3.11/concurrent/futures/thread.py", line 58, in run
    result = self.fn(*self.args, **self.kwargs)
             ^^^^^^^^^^^^^^^^^^^^^^^^^^^^^^^^^^
  File "/home/user-deb/Documents/Projects/django-chat-app/djangovenv/lib/python3.11/site-packages/asgiref/sync.py", line 538, in thread_handler
    return func(*args, **kwargs)
           ^^^^^^^^^^^^^^^^^^^^^
  File "/home/user-deb/Documents/Projects/django-chat-app/chat/views.py", line 8, in chat_view
    chat, created = Chat.objects.get_or_create(name=chat_name)
                    ^^^^^^^^^^^^^^^^^^^^^^^^^^^^^^^^^^^^^^^^^^
  File "/home/user-deb/Documents/Projects/django-chat-app/djangovenv/lib/python3.11/site-packages/django/db/models/manager.py", line 87, in manager_method
    return getattr(self.get_queryset(), name)(*args, **kwargs)
           ^^^^^^^^^^^^^^^^^^^^^^^^^^^^^^^^^^^^^^^^^^^^^^^^^^^
  File "/home/user-deb/Documents/Projects/django-chat-app/djangovenv/lib/python3.11/site-packages/django/db/models/query.py", line 923, in get_or_create
    return self.create(**params), True
           ^^^^^^^^^^^^^^^^^^^^^
  File "/home/user-deb/Documents/Projects/django-chat-app/djangovenv/lib/python3.11/site-packages/django/db/models/query.py", line 658, in create
    obj.save(force_insert=True, using=self.db)
  File "/home/user-deb/Documents/Projects/django-chat-app/chat/models.py", line 62, in save
    super().save(*args, **kwargs)
  File "/home/user-deb/Documents/Projects/django-chat-app/djangovenv/lib/python3.11/site-packages/django/db/models/base.py", line 814, in save
    self.save_base(
  File "/home/user-deb/Documents/Projects/django-chat-app/djangovenv/lib/python3.11/site-packages/django/db/models/base.py", line 877, in save_base
    updated = self._save_table(
              ^^^^^^^^^^^^^^^^^
  File "/home/user-deb/Documents/Projects/django-chat-app/djangovenv/lib/python3.11/site-packages/django/db/models/base.py", line 1020, in _save_table
    results = self._do_insert(
              ^^^^^^^^^^^^^^^^
  File "/home/user-deb/Documents/Projects/django-chat-app/djangovenv/lib/python3.11/site-packages/django/db/models/base.py", line 1061, in _do_insert
    return manager._insert(
           ^^^^^^^^^^^^^^^^
  File "/home/user-deb/Documents/Projects/django-chat-app/djangovenv/lib/python3.11/site-packages/django/db/models/manager.py", line 87, in manager_method
    return getattr(self.get_queryset(), name)(*args, **kwargs)
           ^^^^^^^^^^^^^^^^^^^^^^^^^^^^^^^^^^^^^^^^^^^^^^^^^^^
  File "/home/user-deb/Documents/Projects/django-chat-app/djangovenv/lib/python3.11/site-packages/django/db/models/query.py", line 1805, in _insert
    return query.get_compiler(using=using).execute_sql(returning_fields)
           ^^^^^^^^^^^^^^^^^^^^^^^^^^^^^^^^^^^^^^^^^^^^^^^^^^^^^^^^^^^^^
  File "/home/user-deb/Documents/Projects/django-chat-app/djangovenv/lib/python3.11/site-packages/django/db/models/sql/compiler.py", line 1822, in execute_sql
    cursor.execute(sql, params)
  File "/home/user-deb/Documents/Projects/django-chat-app/djangovenv/lib/python3.11/site-packages/django/db/backends/utils.py", line 102, in execute
    return super().execute(sql, params)
           ^^^^^^^^^^^^^^^^^^^^^^^^^^^^
  File "/home/user-deb/Documents/Projects/django-chat-app/djangovenv/lib/python3.11/site-packages/django/db/backends/utils.py", line 67, in execute
    return self._execute_with_wrappers(
           ^^^^^^^^^^^^^^^^^^^^^^^^^^^^
  File "/home/user-deb/Documents/Projects/django-chat-app/djangovenv/lib/python3.11/site-packages/django/db/backends/utils.py", line 80, in _execute_with_wrappers
    return executor(sql, params, many, context)
           ^^^^^^^^^^^^^^^^^^^^^^^^^^^^^^^^^^^^
  File "/home/user-deb/Documents/Projects/django-chat-app/djangovenv/lib/python3.11/site-packages/django/db/backends/utils.py", line 84, in _execute
    with self.db.wrap_database_errors:
  File "/home/user-deb/Documents/Projects/django-chat-app/djangovenv/lib/python3.11/site-packages/django/db/utils.py", line 91, in __exit__
    raise dj_exc_value.with_traceback(traceback) from exc_value
  File "/home/user-deb/Documents/Projects/django-chat-app/djangovenv/lib/python3.11/site-packages/django/db/backends/utils.py", line 89, in _execute
    return self.cursor.execute(sql, params)
           ^^^^^^^^^^^^^^^^^^^^^^^^^^^^^^^^
  File "/home/user-deb/Documents/Projects/django-chat-app/djangovenv/lib/python3.11/site-packages/django/db/backends/sqlite3/base.py", line 328, in execute
    return super().execute(query, params)
           ^^^^^^^^^^^^^^^^^^^^^^^^^^^^^^
django.db.utils.IntegrityError: NOT NULL constraint failed: chat.id
[35;1mHTTP GET /chat/testing/ 500 [0.03, 127.0.0.1:49000][0m
