Not Found: /
[33mHTTP GET / 404 [0.02, 127.0.0.1:57812][0m
Not Found: /favicon.ico
[33mHTTP GET /favicon.ico 404 [0.01, 127.0.0.1:57812][0m
Not Found: /chat/img/logo.png
Not Found: /chat/img/menu-icon/4.svg
Not Found: /chat/img/menu-icon/1.svg
Not Found: /chat/img/menu-icon/2.svg
[33mHTTP GET /chat/img/logo.png 404 [0.03, 127.0.0.1:32856][0m
[33mHTTP GET /chat/img/menu-icon/4.svg 404 [0.02, 127.0.0.1:32900][0m
[33mHTTP GET /chat/img/menu-icon/1.svg 404 [0.03, 127.0.0.1:32862][0m
[33mHTTP GET /chat/img/menu-icon/2.svg 404 [0.03, 127.0.0.1:32876][0m
Not Found: /chat/img/menu-icon/5.svg
[33mHTTP GET /chat/img/menu-icon/5.svg 404 [0.03, 127.0.0.1:32908][0m
Not Found: /chat/img/menu-icon/3.svg
[33mHTTP GET /chat/img/menu-icon/3.svg 404 [0.03, 127.0.0.1:32884][0m
Not Found: /chat/img/menu-icon/7.svg
[33mHTTP GET /chat/img/menu-icon/7.svg 404 [0.01, 127.0.0.1:32862][0m
Not Found: /chat/img/menu-icon/6.svg
[33mHTTP GET /chat/img/menu-icon/6.svg 404 [0.01, 127.0.0.1:32900][0m
Not Found: /
[33mHTTP GET / 404 [0.01, 127.0.0.1:55990][0m
Not Found: /favicon.ico
Not Found: /accounts/login/
[33mHTTP GET /accounts/login/?next=/chat/ 404 [0.01, 127.0.0.1:58050][0m
Not Found: /accounts/login/
[33mHTTP GET /accounts/login/?next=/chat/ 404 [0.01, 127.0.0.1:58050][0m
Internal Server Error: /chat/
Traceback (most recent call last):
  File "/home/user-deb/Documents/Projects/django-chat-app/djangovenv/lib/python3.11/site-packages/asgiref/sync.py", line 534, in thread_handler
    raise exc_info[1]
  File "/home/user-deb/Documents/Projects/django-chat-app/djangovenv/lib/python3.11/site-packages/django/core/handlers/exception.py", line 42, in inner
    response = await get_response(request)
               ^^^^^^^^^^^^^^^^^^^^^^^^^^^
  File "/home/user-deb/Documents/Projects/django-chat-app/djangovenv/lib/python3.11/site-packages/asgiref/sync.py", line 534, in thread_handler
    raise exc_info[1]
  File "/home/user-deb/Documents/Projects/django-chat-app/djangovenv/lib/python3.11/site-packages/django/core/handlers/base.py", line 253, in _get_response_async
    response = await wrapped_callback(
               ^^^^^^^^^^^^^^^^^^^^^^^
  File "/home/user-deb/Documents/Projects/django-chat-app/djangovenv/lib/python3.11/site-packages/asgiref/sync.py", line 479, in __call__
    ret: _R = await loop.run_in_executor(
              ^^^^^^^^^^^^^^^^^^^^^^^^^^^
  File "/usr/lib/python3.11/concurrent/futures/thread.py", line 58, in run
    result = self.fn(*self.args, **self.kwargs)
             ^^^^^^^^^^^^^^^^^^^^^^^^^^^^^^^^^^
  File "/home/user-deb/Documents/Projects/django-chat-app/djangovenv/lib/python3.11/site-packages/asgiref/sync.py", line 538, in thread_handler
    return func(*args, **kwargs)
           ^^^^^^^^^^^^^^^^^^^^^
  File "/home/user-deb/Documents/Projects/django-chat-app/chat/views.py", line 16, in chat_view
    queryset = request.user.chats.all()
               ^^^^^^^^^^^^^^^^^^
  File "/home/user-deb/Documents/Projects/django-chat-app/djangovenv/lib/python3.11/site-packages/django/utils/functional.py", line 268, in inner
    return func(_wrapped, *args)
           ^^^^^^^^^^^^^^^^^^^^^
AttributeError: 'AnonymousUser' object has no attribute 'chats'
[35;1mHTTP GET /chat/ 500 [0.02, 127.0.0.1:54072][0m
Not Found: /
[33mHTTP GET / 404 [0.01, 127.0.0.1:40344][0m
Not Found: /
[33mHTTP GET / 404 [0.01, 127.0.0.1:58136][0m
Internal Server Error: /user/login/
Traceback (most recent call last):
  File "/home/user-deb/Documents/Projects/django-chat-app/djangovenv/lib/python3.11/site-packages/asgiref/sync.py", line 534, in thread_handler
    raise exc_info[1]
  File "/home/user-deb/Documents/Projects/django-chat-app/djangovenv/lib/python3.11/site-packages/django/core/handlers/exception.py", line 42, in inner
    response = await get_response(request)
               ^^^^^^^^^^^^^^^^^^^^^^^^^^^
  File "/home/user-deb/Documents/Projects/django-chat-app/djangovenv/lib/python3.11/site-packages/asgiref/sync.py", line 534, in thread_handler
    raise exc_info[1]
  File "/home/user-deb/Documents/Projects/django-chat-app/djangovenv/lib/python3.11/site-packages/django/core/handlers/base.py", line 253, in _get_response_async
    response = await wrapped_callback(
               ^^^^^^^^^^^^^^^^^^^^^^^
  File "/home/user-deb/Documents/Projects/django-chat-app/djangovenv/lib/python3.11/site-packages/asgiref/sync.py", line 479, in __call__
    ret: _R = await loop.run_in_executor(
              ^^^^^^^^^^^^^^^^^^^^^^^^^^^
  File "/usr/lib/python3.11/concurrent/futures/thread.py", line 58, in run
    result = self.fn(*self.args, **self.kwargs)
             ^^^^^^^^^^^^^^^^^^^^^^^^^^^^^^^^^^
  File "/home/user-deb/Documents/Projects/django-chat-app/djangovenv/lib/python3.11/site-packages/asgiref/sync.py", line 538, in thread_handler
    return func(*args, **kwargs)
           ^^^^^^^^^^^^^^^^^^^^^
  File "/home/user-deb/Documents/Projects/django-chat-app/user/views.py", line 24, in login_view
    return render(request, 'registration/login.html', {'form': form})
           ^^^^^^^^^^^^^^^^^^^^^^^^^^^^^^^^^^^^^^^^^^^^^^^^^^^^^^^^^^
  File "/home/user-deb/Documents/Projects/django-chat-app/djangovenv/lib/python3.11/site-packages/django/shortcuts.py", line 24, in render
    content = loader.render_to_string(template_name, context, request, using=using)
              ^^^^^^^^^^^^^^^^^^^^^^^^^^^^^^^^^^^^^^^^^^^^^^^^^^^^^^^^^^^^^^^^^^^^^
  File "/home/user-deb/Documents/Projects/django-chat-app/djangovenv/lib/python3.11/site-packages/django/template/loader.py", line 61, in render_to_string
    template = get_template(template_name, using=using)
               ^^^^^^^^^^^^^^^^^^^^^^^^^^^^^^^^^^^^^^^^
  File "/home/user-deb/Documents/Projects/django-chat-app/djangovenv/lib/python3.11/site-packages/django/template/loader.py", line 19, in get_template
    raise TemplateDoesNotExist(template_name, chain=chain)
django.template.exceptions.TemplateDoesNotExist: registration/login.html
[35;1mHTTP GET /user/login/ 500 [0.02, 127.0.0.1:58136][0m
Internal Server Error: /user/register/
Traceback (most recent call last):
  File "/home/user-deb/Documents/Projects/django-chat-app/djangovenv/lib/python3.11/site-packages/django/template/backends/django.py", line 61, in render
    return self.template.render(context)
           ^^^^^^^^^^^^^^^^^^^^^^^^^^^^^
  File "/home/user-deb/Documents/Projects/django-chat-app/djangovenv/lib/python3.11/site-packages/django/template/base.py", line 175, in render
    return self._render(context)
           ^^^^^^^^^^^^^^^^^^^^^
  File "/home/user-deb/Documents/Projects/django-chat-app/djangovenv/lib/python3.11/site-packages/django/template/base.py", line 167, in _render
    return self.nodelist.render(context)
           ^^^^^^^^^^^^^^^^^^^^^^^^^^^^^
  File "/home/user-deb/Documents/Projects/django-chat-app/djangovenv/lib/python3.11/site-packages/django/template/base.py", line 1005, in render
    return SafeString("".join([node.render_annotated(context) for node in self]))
                              ^^^^^^^^^^^^^^^^^^^^^^^^^^^^^^^^^^^^^^^^^^^^^^^^^
  File "/home/user-deb/Documents/Projects/django-chat-app/djangovenv/lib/python3.11/site-packages/django/template/base.py", line 1005, in <listcomp>
    return SafeString("".join([node.render_annotated(context) for node in self]))
                               ^^^^^^^^^^^^^^^^^^^^^^^^^^^^^^
  File "/home/user-deb/Documents/Projects/django-chat-app/djangovenv/lib/python3.11/site-packages/django/template/base.py", line 966, in render_annotated
    return self.render(context)
           ^^^^^^^^^^^^^^^^^^^^
  File "/home/user-deb/Documents/Projects/django-chat-app/djangovenv/lib/python3.11/site-packages/django/template/loader_tags.py", line 132, in render
    compiled_parent = self.get_parent(context)
                      ^^^^^^^^^^^^^^^^^^^^^^^^
  File "/home/user-deb/Documents/Projects/django-chat-app/djangovenv/lib/python3.11/site-packages/django/template/loader_tags.py", line 129, in get_parent
    return self.find_template(parent, context)
           ^^^^^^^^^^^^^^^^^^^^^^^^^^^^^^^^^^^
  File "/home/user-deb/Documents/Projects/django-chat-app/djangovenv/lib/python3.11/site-packages/django/template/loader_tags.py", line 107, in find_template
    template, origin = context.template.engine.find_template(
                       ^^^^^^^^^^^^^^^^^^^^^^^^^^^^^^^^^^^^^^
  File "/home/user-deb/Documents/Projects/django-chat-app/djangovenv/lib/python3.11/site-packages/django/template/engine.py", line 161, in find_template
    raise TemplateDoesNotExist(name, tried=tried)
django.template.exceptions.TemplateDoesNotExist: base.html

The above exception was the direct cause of the following exception:

Traceback (most recent call last):
  File "/home/user-deb/Documents/Projects/django-chat-app/djangovenv/lib/python3.11/site-packages/asgiref/sync.py", line 534, in thread_handler
    raise exc_info[1]
  File "/home/user-deb/Documents/Projects/django-chat-app/djangovenv/lib/python3.11/site-packages/django/core/handlers/exception.py", line 42, in inner
    response = await get_response(request)
               ^^^^^^^^^^^^^^^^^^^^^^^^^^^
  File "/home/user-deb/Documents/Projects/django-chat-app/djangovenv/lib/python3.11/site-packages/asgiref/sync.py", line 534, in thread_handler
    raise exc_info[1]
  File "/home/user-deb/Documents/Projects/django-chat-app/djangovenv/lib/python3.11/site-packages/django/core/handlers/base.py", line 253, in _get_response_async
    response = await wrapped_callback(
               ^^^^^^^^^^^^^^^^^^^^^^^
  File "/home/user-deb/Documents/Projects/django-chat-app/djangovenv/lib/python3.11/site-packages/asgiref/sync.py", line 479, in __call__
    ret: _R = await loop.run_in_executor(
              ^^^^^^^^^^^^^^^^^^^^^^^^^^^
  File "/usr/lib/python3.11/concurrent/futures/thread.py", line 58, in run
    result = self.fn(*self.args, **self.kwargs)
             ^^^^^^^^^^^^^^^^^^^^^^^^^^^^^^^^^^
  File "/home/user-deb/Documents/Projects/django-chat-app/djangovenv/lib/python3.11/site-packages/asgiref/sync.py", line 538, in thread_handler
    return func(*args, **kwargs)
           ^^^^^^^^^^^^^^^^^^^^^
  File "/home/user-deb/Documents/Projects/django-chat-app/user/views.py", line 34, in registration_view
    return render(request, 'user/registration.html', {'form': form})
           ^^^^^^^^^^^^^^^^^^^^^^^^^^^^^^^^^^^^^^^^^^^^^^^^^^^^^^^^^
  File "/home/user-deb/Documents/Projects/django-chat-app/djangovenv/lib/python3.11/site-packages/django/shortcuts.py", line 24, in render
    content = loader.render_to_string(template_name, context, request, using=using)
              ^^^^^^^^^^^^^^^^^^^^^^^^^^^^^^^^^^^^^^^^^^^^^^^^^^^^^^^^^^^^^^^^^^^^^
  File "/home/user-deb/Documents/Projects/django-chat-app/djangovenv/lib/python3.11/site-packages/django/template/loader.py", line 62, in render_to_string
    return template.render(context, request)
           ^^^^^^^^^^^^^^^^^^^^^^^^^^^^^^^^^
  File "/home/user-deb/Documents/Projects/django-chat-app/djangovenv/lib/python3.11/site-packages/django/template/backends/django.py", line 63, in render
    reraise(exc, self.backend)
  File "/home/user-deb/Documents/Projects/django-chat-app/djangovenv/lib/python3.11/site-packages/django/template/backends/django.py", line 84, in reraise
    raise new from exc
django.template.exceptions.TemplateDoesNotExist: base.html
[35;1mHTTP GET /user/register/ 500 [0.02, 127.0.0.1:48122][0m
Internal Server Error: /user/register/
Traceback (most recent call last):
  File "/home/user-deb/Documents/Projects/django-chat-app/djangovenv/lib/python3.11/site-packages/asgiref/sync.py", line 534, in thread_handler
    raise exc_info[1]
  File "/home/user-deb/Documents/Projects/django-chat-app/djangovenv/lib/python3.11/site-packages/django/core/handlers/exception.py", line 42, in inner
    response = await get_response(request)
               ^^^^^^^^^^^^^^^^^^^^^^^^^^^
  File "/home/user-deb/Documents/Projects/django-chat-app/djangovenv/lib/python3.11/site-packages/asgiref/sync.py", line 534, in thread_handler
    raise exc_info[1]
  File "/home/user-deb/Documents/Projects/django-chat-app/djangovenv/lib/python3.11/site-packages/django/core/handlers/base.py", line 253, in _get_response_async
    response = await wrapped_callback(
               ^^^^^^^^^^^^^^^^^^^^^^^
  File "/home/user-deb/Documents/Projects/django-chat-app/djangovenv/lib/python3.11/site-packages/asgiref/sync.py", line 479, in __call__
    ret: _R = await loop.run_in_executor(
              ^^^^^^^^^^^^^^^^^^^^^^^^^^^
  File "/usr/lib/python3.11/concurrent/futures/thread.py", line 58, in run
    result = self.fn(*self.args, **self.kwargs)
             ^^^^^^^^^^^^^^^^^^^^^^^^^^^^^^^^^^
  File "/home/user-deb/Documents/Projects/django-chat-app/djangovenv/lib/python3.11/site-packages/asgiref/sync.py", line 538, in thread_handler
    return func(*args, **kwargs)
           ^^^^^^^^^^^^^^^^^^^^^
  File "/home/user-deb/Documents/Projects/django-chat-app/user/views.py", line 38, in registration_view
    if form.is_valid():
       ^^^^^^^^^^^^^^^
  File "/home/user-deb/Documents/Projects/django-chat-app/djangovenv/lib/python3.11/site-packages/django/forms/forms.py", line 201, in is_valid
    return self.is_bound and not self.errors
                                 ^^^^^^^^^^^
  File "/home/user-deb/Documents/Projects/django-chat-app/djangovenv/lib/python3.11/site-packages/django/forms/forms.py", line 196, in errors
    self.full_clean()
  File "/home/user-deb/Documents/Projects/django-chat-app/djangovenv/lib/python3.11/site-packages/django/forms/forms.py", line 433, in full_clean
    self._clean_fields()
  File "/home/user-deb/Documents/Projects/django-chat-app/djangovenv/lib/python3.11/site-packages/django/forms/forms.py", line 440, in _clean_fields
    value = bf.initial if field.disabled else bf.data
                                              ^^^^^^^
  File "/home/user-deb/Documents/Projects/django-chat-app/djangovenv/lib/python3.11/site-packages/django/forms/boundfield.py", line 135, in data
    return self.form._widget_data_value(self.field.widget, self.html_name)
           ^^^^^^^^^^^^^^^^^^^^^^^^^^^^^^^^^^^^^^^^^^^^^^^^^^^^^^^^^^^^^^^
  File "/home/user-deb/Documents/Projects/django-chat-app/djangovenv/lib/python3.11/site-packages/django/forms/forms.py", line 220, in _widget_data_value
    return widget.value_from_datadict(self.data, self.files, html_name)
           ^^^^^^^^^^^^^^^^^^^^^^^^^^^^^^^^^^^^^^^^^^^^^^^^^^^^^^^^^^^^
  File "/home/user-deb/Documents/Projects/django-chat-app/djangovenv/lib/python3.11/site-packages/django/forms/widgets.py", line 297, in value_from_datadict
    return data.get(name)
           ^^^^^^^^
AttributeError: 'ASGIRequest' object has no attribute 'get'
[35;1mHTTP POST /user/register/ 500 [0.02, 127.0.0.1:48122][0m
Not Found: /accounts/login/
[33mHTTP GET /accounts/login/?next=/chat/ 404 [0.01, 127.0.0.1:57276][0m
Not Found: /accounts/login/
[33mHTTP GET /accounts/login/?next=/chat/ 404 [0.00, 127.0.0.1:57276][0m
Not Found: /accounts/login/
[33mHTTP GET /accounts/login/?next=/chat/ 404 [0.01, 127.0.0.1:57276][0m
Not Found: /achat
[33mHTTP GET /achat 404 [0.00, 127.0.0.1:57276][0m
Not Found: /accounts/login/
[33mHTTP GET /accounts/login/?next=/chat/ 404 [0.00, 127.0.0.1:57276][0m
Internal Server Error: /user/register/
Traceback (most recent call last):
  File "/home/user-deb/Documents/Projects/django-chat-app/djangovenv/lib/python3.11/site-packages/asgiref/sync.py", line 534, in thread_handler
    raise exc_info[1]
  File "/home/user-deb/Documents/Projects/django-chat-app/djangovenv/lib/python3.11/site-packages/django/core/handlers/exception.py", line 42, in inner
    response = await get_response(request)
               ^^^^^^^^^^^^^^^^^^^^^^^^^^^
  File "/home/user-deb/Documents/Projects/django-chat-app/djangovenv/lib/python3.11/site-packages/asgiref/sync.py", line 534, in thread_handler
    raise exc_info[1]
  File "/home/user-deb/Documents/Projects/django-chat-app/djangovenv/lib/python3.11/site-packages/django/core/handlers/base.py", line 253, in _get_response_async
    response = await wrapped_callback(
               ^^^^^^^^^^^^^^^^^^^^^^^
  File "/home/user-deb/Documents/Projects/django-chat-app/djangovenv/lib/python3.11/site-packages/asgiref/sync.py", line 479, in __call__
    ret: _R = await loop.run_in_executor(
              ^^^^^^^^^^^^^^^^^^^^^^^^^^^
  File "/usr/lib/python3.11/concurrent/futures/thread.py", line 58, in run
    result = self.fn(*self.args, **self.kwargs)
             ^^^^^^^^^^^^^^^^^^^^^^^^^^^^^^^^^^
  File "/home/user-deb/Documents/Projects/django-chat-app/djangovenv/lib/python3.11/site-packages/asgiref/sync.py", line 538, in thread_handler
    return func(*args, **kwargs)
           ^^^^^^^^^^^^^^^^^^^^^
  File "/home/user-deb/Documents/Projects/django-chat-app/user/views.py", line 38, in registration_view
    if form.is_valid():
       ^^^^^^^^^^^^^^^
  File "/home/user-deb/Documents/Projects/django-chat-app/djangovenv/lib/python3.11/site-packages/django/forms/forms.py", line 201, in is_valid
    return self.is_bound and not self.errors
                                 ^^^^^^^^^^^
  File "/home/user-deb/Documents/Projects/django-chat-app/djangovenv/lib/python3.11/site-packages/django/forms/forms.py", line 196, in errors
    self.full_clean()
  File "/home/user-deb/Documents/Projects/django-chat-app/djangovenv/lib/python3.11/site-packages/django/forms/forms.py", line 433, in full_clean
    self._clean_fields()
  File "/home/user-deb/Documents/Projects/django-chat-app/djangovenv/lib/python3.11/site-packages/django/forms/forms.py", line 440, in _clean_fields
    value = bf.initial if field.disabled else bf.data
                                              ^^^^^^^
  File "/home/user-deb/Documents/Projects/django-chat-app/djangovenv/lib/python3.11/site-packages/django/forms/boundfield.py", line 135, in data
    return self.form._widget_data_value(self.field.widget, self.html_name)
           ^^^^^^^^^^^^^^^^^^^^^^^^^^^^^^^^^^^^^^^^^^^^^^^^^^^^^^^^^^^^^^^
  File "/home/user-deb/Documents/Projects/django-chat-app/djangovenv/lib/python3.11/site-packages/django/forms/forms.py", line 220, in _widget_data_value
    return widget.value_from_datadict(self.data, self.files, html_name)
           ^^^^^^^^^^^^^^^^^^^^^^^^^^^^^^^^^^^^^^^^^^^^^^^^^^^^^^^^^^^^
  File "/home/user-deb/Documents/Projects/django-chat-app/djangovenv/lib/python3.11/site-packages/django/forms/widgets.py", line 297, in value_from_datadict
    return data.get(name)
           ^^^^^^^^
AttributeError: 'ASGIRequest' object has no attribute 'get'
[35;1mHTTP POST /user/register/ 500 [0.02, 127.0.0.1:57276][0m
Not Found: /accounts/login/
[33mHTTP GET /accounts/login/?next=/chat/ 404 [0.01, 127.0.0.1:52092][0m
Not Found: /favicon.ico
[33mHTTP GET /favicon.ico 404 [0.01, 127.0.0.1:57046][0m
Not Found: /favicon.ico
[33mHTTP GET /favicon.ico 404 [0.00, 127.0.0.1:57046][0m
Not Found: /favicon.ico
[33mHTTP GET /favicon.ico 404 [0.01, 127.0.0.1:57046][0m
Not Found: /favicon.ico
[33mHTTP GET /favicon.ico 404 [0.01, 127.0.0.1:58616][0m
Not Found: /favicon.ico
[33mHTTP GET /favicon.ico 404 [0.01, 127.0.0.1:57354][0m
Not Found: /favicon.ico
[33mHTTP GET /favicon.ico 404 [0.01, 127.0.0.1:57354][0m
Not Found: /favicon.ico
[33mHTTP GET /favicon.ico 404 [0.00, 127.0.0.1:57354][0m
Not Found: /favicon.ico
[33mHTTP GET /favicon.ico 404 [0.00, 127.0.0.1:57354][0m
Not Found: /favicon.ico
[33mHTTP GET /favicon.ico 404 [0.00, 127.0.0.1:57354][0m
Internal Server Error: /user/login/
Traceback (most recent call last):
  File "/home/user-deb/Documents/Projects/django-chat-app/djangovenv/lib/python3.11/site-packages/asgiref/sync.py", line 534, in thread_handler
    raise exc_info[1]
  File "/home/user-deb/Documents/Projects/django-chat-app/djangovenv/lib/python3.11/site-packages/django/core/handlers/exception.py", line 42, in inner
    response = await get_response(request)
               ^^^^^^^^^^^^^^^^^^^^^^^^^^^
  File "/home/user-deb/Documents/Projects/django-chat-app/djangovenv/lib/python3.11/site-packages/asgiref/sync.py", line 534, in thread_handler
    raise exc_info[1]
  File "/home/user-deb/Documents/Projects/django-chat-app/djangovenv/lib/python3.11/site-packages/django/core/handlers/base.py", line 253, in _get_response_async
    response = await wrapped_callback(
               ^^^^^^^^^^^^^^^^^^^^^^^
  File "/home/user-deb/Documents/Projects/django-chat-app/djangovenv/lib/python3.11/site-packages/asgiref/sync.py", line 479, in __call__
    ret: _R = await loop.run_in_executor(
              ^^^^^^^^^^^^^^^^^^^^^^^^^^^
  File "/usr/lib/python3.11/concurrent/futures/thread.py", line 58, in run
    result = self.fn(*self.args, **self.kwargs)
             ^^^^^^^^^^^^^^^^^^^^^^^^^^^^^^^^^^
  File "/home/user-deb/Documents/Projects/django-chat-app/djangovenv/lib/python3.11/site-packages/asgiref/sync.py", line 538, in thread_handler
    return func(*args, **kwargs)
           ^^^^^^^^^^^^^^^^^^^^^
  File "/home/user-deb/Documents/Projects/django-chat-app/user/views.py", line 10, in login_view
    print(form.cleaned_data['username'])
          ^^^^^^^^^^^^^^^^^
AttributeError: 'CustomLoginForm' object has no attribute 'cleaned_data'
[35;1mHTTP POST /user/login/ 500 [0.02, 127.0.0.1:58440][0m
Not Found: /favicon.ico
